{
 "cells": [
  {
   "cell_type": "code",
   "execution_count": 8,
   "id": "3e989666",
   "metadata": {},
   "outputs": [
    {
     "name": "stdout",
     "output_type": "stream",
     "text": [
      "Requirement already satisfied: python-telegram-bot==13.3 in c:\\programdata\\anaconda3\\lib\\site-packages (13.3)\n",
      "Requirement already satisfied: tornado>=5.1 in c:\\programdata\\anaconda3\\lib\\site-packages (from python-telegram-bot==13.3) (6.1)\n",
      "Requirement already satisfied: APScheduler==3.6.3 in c:\\programdata\\anaconda3\\lib\\site-packages (from python-telegram-bot==13.3) (3.6.3)\n",
      "Requirement already satisfied: certifi in c:\\programdata\\anaconda3\\lib\\site-packages (from python-telegram-bot==13.3) (2021.10.8)\n",
      "Requirement already satisfied: pytz>=2018.6 in c:\\programdata\\anaconda3\\lib\\site-packages (from python-telegram-bot==13.3) (2021.3)\n",
      "Requirement already satisfied: six>=1.4.0 in c:\\programdata\\anaconda3\\lib\\site-packages (from APScheduler==3.6.3->python-telegram-bot==13.3) (1.16.0)\n",
      "Requirement already satisfied: tzlocal>=1.2 in c:\\programdata\\anaconda3\\lib\\site-packages (from APScheduler==3.6.3->python-telegram-bot==13.3) (4.2)\n",
      "Requirement already satisfied: setuptools>=0.7 in c:\\programdata\\anaconda3\\lib\\site-packages (from APScheduler==3.6.3->python-telegram-bot==13.3) (58.0.4)\n",
      "Requirement already satisfied: pytz-deprecation-shim in c:\\programdata\\anaconda3\\lib\\site-packages (from tzlocal>=1.2->APScheduler==3.6.3->python-telegram-bot==13.3) (0.1.0.post0)\n",
      "Requirement already satisfied: tzdata in c:\\programdata\\anaconda3\\lib\\site-packages (from tzlocal>=1.2->APScheduler==3.6.3->python-telegram-bot==13.3) (2022.7)\n",
      "Note: you may need to restart the kernel to use updated packages.\n"
     ]
    },
    {
     "name": "stderr",
     "output_type": "stream",
     "text": [
      "WARNING: Ignoring invalid distribution -yio (c:\\programdata\\anaconda3\\lib\\site-packages)\n",
      "WARNING: Ignoring invalid distribution -nyio (c:\\programdata\\anaconda3\\lib\\site-packages)\n",
      "WARNING: Ignoring invalid distribution - (c:\\programdata\\anaconda3\\lib\\site-packages)\n",
      "WARNING: Ignoring invalid distribution -yio (c:\\programdata\\anaconda3\\lib\\site-packages)\n",
      "WARNING: Ignoring invalid distribution -nyio (c:\\programdata\\anaconda3\\lib\\site-packages)\n",
      "WARNING: Ignoring invalid distribution - (c:\\programdata\\anaconda3\\lib\\site-packages)\n",
      "WARNING: Ignoring invalid distribution -yio (c:\\programdata\\anaconda3\\lib\\site-packages)\n",
      "WARNING: Ignoring invalid distribution -nyio (c:\\programdata\\anaconda3\\lib\\site-packages)\n",
      "WARNING: Ignoring invalid distribution - (c:\\programdata\\anaconda3\\lib\\site-packages)\n",
      "WARNING: Ignoring invalid distribution -yio (c:\\programdata\\anaconda3\\lib\\site-packages)\n",
      "WARNING: Ignoring invalid distribution -nyio (c:\\programdata\\anaconda3\\lib\\site-packages)\n",
      "WARNING: Ignoring invalid distribution - (c:\\programdata\\anaconda3\\lib\\site-packages)\n",
      "WARNING: Ignoring invalid distribution -yio (c:\\programdata\\anaconda3\\lib\\site-packages)\n",
      "WARNING: Ignoring invalid distribution -nyio (c:\\programdata\\anaconda3\\lib\\site-packages)\n",
      "WARNING: Ignoring invalid distribution - (c:\\programdata\\anaconda3\\lib\\site-packages)\n",
      "WARNING: Ignoring invalid distribution -yio (c:\\programdata\\anaconda3\\lib\\site-packages)\n",
      "WARNING: Ignoring invalid distribution -nyio (c:\\programdata\\anaconda3\\lib\\site-packages)\n",
      "WARNING: Ignoring invalid distribution - (c:\\programdata\\anaconda3\\lib\\site-packages)\n"
     ]
    }
   ],
   "source": [
    "pip install python-telegram-bot==13.3"
   ]
  },
  {
   "cell_type": "code",
   "execution_count": 9,
   "id": "2b02458b",
   "metadata": {},
   "outputs": [],
   "source": [
    "from telegram import *"
   ]
  },
  {
   "cell_type": "code",
   "execution_count": 10,
   "id": "a15775fb",
   "metadata": {},
   "outputs": [],
   "source": [
    "import telegram.ext\n",
    "from telegram.ext import *"
   ]
  },
  {
   "cell_type": "code",
   "execution_count": 11,
   "id": "67285bb8",
   "metadata": {},
   "outputs": [],
   "source": [
    "from telegram import Update, ForceReply\n",
    "from telegram.ext import Updater, CommandHandler, MessageHandler, Filters, CallbackContext "
   ]
  },
  {
   "cell_type": "code",
   "execution_count": 12,
   "id": "b2b13e24",
   "metadata": {},
   "outputs": [],
   "source": [
    "Token=\"YOUR TOKEN"
   ]
  },
  {
   "cell_type": "code",
   "execution_count": 13,
   "id": "dff2feb6",
   "metadata": {},
   "outputs": [],
   "source": [
    "updater= Updater(\"Your Token")",
    "dispatcher=updater.dispatcher"
   ]
  },
  {
   "cell_type": "code",
   "execution_count": 14,
   "id": "361bd099",
   "metadata": {},
   "outputs": [],
   "source": [
    "def start(update,context):\n",
    "    update.message.reply_text(\"Hello! Learn about Telegram bot\")"
   ]
  },
  {
   "cell_type": "code",
   "execution_count": 15,
   "id": "c90dc8b2",
   "metadata": {},
   "outputs": [],
   "source": [
    "def help(update,context):\n",
    "    update.message.reply_text(\n",
    "        \"\"\"\n",
    "        /start-> Welcome \n",
    "/help-> Message\n",
    "/content-> Options\n",
    "/Python-> Python playlist\n",
    "/DSwithPython-> DS with Python playlist\n",
    "/problemsolving-> Problem solving with python playlist\n",
    "        \"\"\"\n",
    "    )"
   ]
  },
  {
   "cell_type": "code",
   "execution_count": 16,
   "id": "f256cb0f",
   "metadata": {},
   "outputs": [],
   "source": [
    "def content(update, context):\n",
    "    update.message.reply_text(\"We have various articles and playlists available\")"
   ]
  },
  {
   "cell_type": "code",
   "execution_count": 17,
   "id": "c853b4f4",
   "metadata": {},
   "outputs": [],
   "source": [
    "def Python(update, context):\n",
    "    update.message.reply_text(\"Learn Python :https://youtube.com/playlist?list=PLBZBJbE_rGRWeh5mIBhD-hhDwSEDxogDg \")"
   ]
  },
  {
   "cell_type": "code",
   "execution_count": 18,
   "id": "682cbb90",
   "metadata": {},
   "outputs": [],
   "source": [
    "def DSwithPython(update, context):\n",
    "    update.message.reply_test(\"Learn Data Structure with Python https://youtube.com/playlist?list=PLeo1K3hjS3uu_n_a__MI_KktGTLYopZ12\")"
   ]
  },
  {
   "cell_type": "code",
   "execution_count": 19,
   "id": "37db9e97",
   "metadata": {},
   "outputs": [],
   "source": [
    "def Problemsolving(update, context):\n",
    "    update.message.reply_text(\"Problem solving using Python https://youtube.com/playlist?list=PLH1n1sJO7tbxmE36txTPhgidmW5Z9Bn7m\")"
   ]
  },
  {
   "cell_type": "code",
   "execution_count": 20,
   "id": "abcf7f95",
   "metadata": {},
   "outputs": [],
   "source": [
    "dispatcher.add_handler(CommandHandler('start',start))"
   ]
  },
  {
   "cell_type": "code",
   "execution_count": 21,
   "id": "2e794bb6",
   "metadata": {},
   "outputs": [],
   "source": [
    "dispatcher.add_handler(CommandHandler('start',start))"
   ]
  },
  {
   "cell_type": "code",
   "execution_count": 22,
   "id": "b48a4484",
   "metadata": {},
   "outputs": [],
   "source": [
    "dispatcher.add_handler(CommandHandler('content',content))"
   ]
  },
  {
   "cell_type": "code",
   "execution_count": 23,
   "id": "03001f8f",
   "metadata": {},
   "outputs": [],
   "source": [
    "dispatcher.add_handler(CommandHandler('Python',Python))"
   ]
  },
  {
   "cell_type": "code",
   "execution_count": 24,
   "id": "12a8bf36",
   "metadata": {},
   "outputs": [],
   "source": [
    "dispatcher.add_handler(CommandHandler('DSwithPython',DSwithPython))"
   ]
  },
  {
   "cell_type": "code",
   "execution_count": 25,
   "id": "4edca09b",
   "metadata": {},
   "outputs": [],
   "source": [
    "dispatcher.add_handler(CommandHandler('Problemsolving',Problemsolving))"
   ]
  },
  {
   "cell_type": "code",
   "execution_count": 26,
   "id": "bf10ad07",
   "metadata": {},
   "outputs": [],
   "source": [
    "dispatcher.add_handler(CommandHandler('help',help))"
   ]
  },
  {
   "cell_type": "code",
   "execution_count": 27,
   "id": "4549277c",
   "metadata": {
    "scrolled": true
   },
   "outputs": [
    {
     "data": {
      "text/plain": [
       "<queue.Queue at 0x2d016c54970>"
      ]
     },
     "execution_count": 27,
     "metadata": {},
     "output_type": "execute_result"
    }
   ],
   "source": [
    "updater.start_polling()"
   ]
  },
  {
   "cell_type": "code",
   "execution_count": null,
   "id": "26b9601a",
   "metadata": {},
   "outputs": [
    {
     "name": "stderr",
     "output_type": "stream",
     "text": [
      "Error while getting Updates: Conflict: terminated by other getUpdates request; make sure that only one bot instance is running\n",
      "No error handlers are registered, logging exception.\n",
      "Traceback (most recent call last):\n",
      "  File \"C:\\ProgramData\\Anaconda3\\lib\\site-packages\\telegram\\ext\\updater.py\", line 465, in _network_loop_retry\n",
      "    if not action_cb():\n",
      "  File \"C:\\ProgramData\\Anaconda3\\lib\\site-packages\\telegram\\ext\\updater.py\", line 416, in polling_action_cb\n",
      "    updates = self.bot.get_updates(\n",
      "  File \"C:\\ProgramData\\Anaconda3\\lib\\site-packages\\telegram\\bot.py\", line 126, in decorator\n",
      "    result = func(*args, **kwargs)\n",
      "  File \"C:\\ProgramData\\Anaconda3\\lib\\site-packages\\telegram\\bot.py\", line 2748, in get_updates\n",
      "    result = self._post(\n",
      "  File \"C:\\ProgramData\\Anaconda3\\lib\\site-packages\\telegram\\bot.py\", line 258, in _post\n",
      "    return self.request.post(\n",
      "  File \"C:\\ProgramData\\Anaconda3\\lib\\site-packages\\telegram\\utils\\request.py\", line 349, in post\n",
      "    result = self._request_wrapper(\n",
      "  File \"C:\\ProgramData\\Anaconda3\\lib\\site-packages\\telegram\\utils\\request.py\", line 276, in _request_wrapper\n",
      "    raise Conflict(message)\n",
      "telegram.error.Conflict: Conflict: terminated by other getUpdates request; make sure that only one bot instance is running\n",
      "Error while getting Updates: Conflict: terminated by other getUpdates request; make sure that only one bot instance is running\n",
      "No error handlers are registered, logging exception.\n",
      "Traceback (most recent call last):\n",
      "  File \"C:\\ProgramData\\Anaconda3\\lib\\site-packages\\telegram\\ext\\updater.py\", line 465, in _network_loop_retry\n",
      "    if not action_cb():\n",
      "  File \"C:\\ProgramData\\Anaconda3\\lib\\site-packages\\telegram\\ext\\updater.py\", line 416, in polling_action_cb\n",
      "    updates = self.bot.get_updates(\n",
      "  File \"C:\\ProgramData\\Anaconda3\\lib\\site-packages\\telegram\\bot.py\", line 126, in decorator\n",
      "    result = func(*args, **kwargs)\n",
      "  File \"C:\\ProgramData\\Anaconda3\\lib\\site-packages\\telegram\\bot.py\", line 2748, in get_updates\n",
      "    result = self._post(\n",
      "  File \"C:\\ProgramData\\Anaconda3\\lib\\site-packages\\telegram\\bot.py\", line 258, in _post\n",
      "    return self.request.post(\n",
      "  File \"C:\\ProgramData\\Anaconda3\\lib\\site-packages\\telegram\\utils\\request.py\", line 349, in post\n",
      "    result = self._request_wrapper(\n",
      "  File \"C:\\ProgramData\\Anaconda3\\lib\\site-packages\\telegram\\utils\\request.py\", line 276, in _request_wrapper\n",
      "    raise Conflict(message)\n",
      "telegram.error.Conflict: Conflict: terminated by other getUpdates request; make sure that only one bot instance is running\n",
      "Error while getting Updates: Conflict: terminated by other getUpdates request; make sure that only one bot instance is running\n",
      "No error handlers are registered, logging exception.\n",
      "Traceback (most recent call last):\n",
      "  File \"C:\\ProgramData\\Anaconda3\\lib\\site-packages\\telegram\\ext\\updater.py\", line 465, in _network_loop_retry\n",
      "    if not action_cb():\n",
      "  File \"C:\\ProgramData\\Anaconda3\\lib\\site-packages\\telegram\\ext\\updater.py\", line 416, in polling_action_cb\n",
      "    updates = self.bot.get_updates(\n",
      "  File \"C:\\ProgramData\\Anaconda3\\lib\\site-packages\\telegram\\bot.py\", line 126, in decorator\n",
      "    result = func(*args, **kwargs)\n",
      "  File \"C:\\ProgramData\\Anaconda3\\lib\\site-packages\\telegram\\bot.py\", line 2748, in get_updates\n",
      "    result = self._post(\n",
      "  File \"C:\\ProgramData\\Anaconda3\\lib\\site-packages\\telegram\\bot.py\", line 258, in _post\n",
      "    return self.request.post(\n",
      "  File \"C:\\ProgramData\\Anaconda3\\lib\\site-packages\\telegram\\utils\\request.py\", line 349, in post\n",
      "    result = self._request_wrapper(\n",
      "  File \"C:\\ProgramData\\Anaconda3\\lib\\site-packages\\telegram\\utils\\request.py\", line 276, in _request_wrapper\n",
      "    raise Conflict(message)\n",
      "telegram.error.Conflict: Conflict: terminated by other getUpdates request; make sure that only one bot instance is running\n",
      "Error while getting Updates: Conflict: terminated by other getUpdates request; make sure that only one bot instance is running\n",
      "No error handlers are registered, logging exception.\n",
      "Traceback (most recent call last):\n",
      "  File \"C:\\ProgramData\\Anaconda3\\lib\\site-packages\\telegram\\ext\\updater.py\", line 465, in _network_loop_retry\n",
      "    if not action_cb():\n",
      "  File \"C:\\ProgramData\\Anaconda3\\lib\\site-packages\\telegram\\ext\\updater.py\", line 416, in polling_action_cb\n",
      "    updates = self.bot.get_updates(\n",
      "  File \"C:\\ProgramData\\Anaconda3\\lib\\site-packages\\telegram\\bot.py\", line 126, in decorator\n",
      "    result = func(*args, **kwargs)\n",
      "  File \"C:\\ProgramData\\Anaconda3\\lib\\site-packages\\telegram\\bot.py\", line 2748, in get_updates\n",
      "    result = self._post(\n",
      "  File \"C:\\ProgramData\\Anaconda3\\lib\\site-packages\\telegram\\bot.py\", line 258, in _post\n",
      "    return self.request.post(\n",
      "  File \"C:\\ProgramData\\Anaconda3\\lib\\site-packages\\telegram\\utils\\request.py\", line 349, in post\n",
      "    result = self._request_wrapper(\n",
      "  File \"C:\\ProgramData\\Anaconda3\\lib\\site-packages\\telegram\\utils\\request.py\", line 276, in _request_wrapper\n",
      "    raise Conflict(message)\n",
      "telegram.error.Conflict: Conflict: terminated by other getUpdates request; make sure that only one bot instance is running\n",
      "Error while getting Updates: Conflict: terminated by other getUpdates request; make sure that only one bot instance is running\n",
      "No error handlers are registered, logging exception.\n",
      "Traceback (most recent call last):\n",
      "  File \"C:\\ProgramData\\Anaconda3\\lib\\site-packages\\telegram\\ext\\updater.py\", line 465, in _network_loop_retry\n",
      "    if not action_cb():\n",
      "  File \"C:\\ProgramData\\Anaconda3\\lib\\site-packages\\telegram\\ext\\updater.py\", line 416, in polling_action_cb\n",
      "    updates = self.bot.get_updates(\n",
      "  File \"C:\\ProgramData\\Anaconda3\\lib\\site-packages\\telegram\\bot.py\", line 126, in decorator\n",
      "    result = func(*args, **kwargs)\n",
      "  File \"C:\\ProgramData\\Anaconda3\\lib\\site-packages\\telegram\\bot.py\", line 2748, in get_updates\n",
      "    result = self._post(\n",
      "  File \"C:\\ProgramData\\Anaconda3\\lib\\site-packages\\telegram\\bot.py\", line 258, in _post\n",
      "    return self.request.post(\n",
      "  File \"C:\\ProgramData\\Anaconda3\\lib\\site-packages\\telegram\\utils\\request.py\", line 349, in post\n",
      "    result = self._request_wrapper(\n",
      "  File \"C:\\ProgramData\\Anaconda3\\lib\\site-packages\\telegram\\utils\\request.py\", line 276, in _request_wrapper\n",
      "    raise Conflict(message)\n",
      "telegram.error.Conflict: Conflict: terminated by other getUpdates request; make sure that only one bot instance is running\n",
      "Error while getting Updates: Conflict: terminated by other getUpdates request; make sure that only one bot instance is running\n",
      "No error handlers are registered, logging exception.\n",
      "Traceback (most recent call last):\n",
      "  File \"C:\\ProgramData\\Anaconda3\\lib\\site-packages\\telegram\\ext\\updater.py\", line 465, in _network_loop_retry\n",
      "    if not action_cb():\n",
      "  File \"C:\\ProgramData\\Anaconda3\\lib\\site-packages\\telegram\\ext\\updater.py\", line 416, in polling_action_cb\n",
      "    updates = self.bot.get_updates(\n",
      "  File \"C:\\ProgramData\\Anaconda3\\lib\\site-packages\\telegram\\bot.py\", line 126, in decorator\n",
      "    result = func(*args, **kwargs)\n",
      "  File \"C:\\ProgramData\\Anaconda3\\lib\\site-packages\\telegram\\bot.py\", line 2748, in get_updates\n",
      "    result = self._post(\n",
      "  File \"C:\\ProgramData\\Anaconda3\\lib\\site-packages\\telegram\\bot.py\", line 258, in _post\n",
      "    return self.request.post(\n",
      "  File \"C:\\ProgramData\\Anaconda3\\lib\\site-packages\\telegram\\utils\\request.py\", line 349, in post\n",
      "    result = self._request_wrapper(\n",
      "  File \"C:\\ProgramData\\Anaconda3\\lib\\site-packages\\telegram\\utils\\request.py\", line 276, in _request_wrapper\n",
      "    raise Conflict(message)\n",
      "telegram.error.Conflict: Conflict: terminated by other getUpdates request; make sure that only one bot instance is running\n",
      "Error while getting Updates: Conflict: terminated by other getUpdates request; make sure that only one bot instance is running\n",
      "No error handlers are registered, logging exception.\n",
      "Traceback (most recent call last):\n",
      "  File \"C:\\ProgramData\\Anaconda3\\lib\\site-packages\\telegram\\ext\\updater.py\", line 465, in _network_loop_retry\n",
      "    if not action_cb():\n",
      "  File \"C:\\ProgramData\\Anaconda3\\lib\\site-packages\\telegram\\ext\\updater.py\", line 416, in polling_action_cb\n",
      "    updates = self.bot.get_updates(\n",
      "  File \"C:\\ProgramData\\Anaconda3\\lib\\site-packages\\telegram\\bot.py\", line 126, in decorator\n",
      "    result = func(*args, **kwargs)\n",
      "  File \"C:\\ProgramData\\Anaconda3\\lib\\site-packages\\telegram\\bot.py\", line 2748, in get_updates\n",
      "    result = self._post(\n",
      "  File \"C:\\ProgramData\\Anaconda3\\lib\\site-packages\\telegram\\bot.py\", line 258, in _post\n",
      "    return self.request.post(\n",
      "  File \"C:\\ProgramData\\Anaconda3\\lib\\site-packages\\telegram\\utils\\request.py\", line 349, in post\n",
      "    result = self._request_wrapper(\n",
      "  File \"C:\\ProgramData\\Anaconda3\\lib\\site-packages\\telegram\\utils\\request.py\", line 276, in _request_wrapper\n",
      "    raise Conflict(message)\n",
      "telegram.error.Conflict: Conflict: terminated by other getUpdates request; make sure that only one bot instance is running\n"
     ]
    },
    {
     "name": "stderr",
     "output_type": "stream",
     "text": [
      "Error while getting Updates: Conflict: terminated by other getUpdates request; make sure that only one bot instance is running\n",
      "No error handlers are registered, logging exception.\n",
      "Traceback (most recent call last):\n",
      "  File \"C:\\ProgramData\\Anaconda3\\lib\\site-packages\\telegram\\ext\\updater.py\", line 465, in _network_loop_retry\n",
      "    if not action_cb():\n",
      "  File \"C:\\ProgramData\\Anaconda3\\lib\\site-packages\\telegram\\ext\\updater.py\", line 416, in polling_action_cb\n",
      "    updates = self.bot.get_updates(\n",
      "  File \"C:\\ProgramData\\Anaconda3\\lib\\site-packages\\telegram\\bot.py\", line 126, in decorator\n",
      "    result = func(*args, **kwargs)\n",
      "  File \"C:\\ProgramData\\Anaconda3\\lib\\site-packages\\telegram\\bot.py\", line 2748, in get_updates\n",
      "    result = self._post(\n",
      "  File \"C:\\ProgramData\\Anaconda3\\lib\\site-packages\\telegram\\bot.py\", line 258, in _post\n",
      "    return self.request.post(\n",
      "  File \"C:\\ProgramData\\Anaconda3\\lib\\site-packages\\telegram\\utils\\request.py\", line 349, in post\n",
      "    result = self._request_wrapper(\n",
      "  File \"C:\\ProgramData\\Anaconda3\\lib\\site-packages\\telegram\\utils\\request.py\", line 276, in _request_wrapper\n",
      "    raise Conflict(message)\n",
      "telegram.error.Conflict: Conflict: terminated by other getUpdates request; make sure that only one bot instance is running\n",
      "Error while getting Updates: Conflict: terminated by other getUpdates request; make sure that only one bot instance is running\n",
      "No error handlers are registered, logging exception.\n",
      "Traceback (most recent call last):\n",
      "  File \"C:\\ProgramData\\Anaconda3\\lib\\site-packages\\telegram\\ext\\updater.py\", line 465, in _network_loop_retry\n",
      "    if not action_cb():\n",
      "  File \"C:\\ProgramData\\Anaconda3\\lib\\site-packages\\telegram\\ext\\updater.py\", line 416, in polling_action_cb\n",
      "    updates = self.bot.get_updates(\n",
      "  File \"C:\\ProgramData\\Anaconda3\\lib\\site-packages\\telegram\\bot.py\", line 126, in decorator\n",
      "    result = func(*args, **kwargs)\n",
      "  File \"C:\\ProgramData\\Anaconda3\\lib\\site-packages\\telegram\\bot.py\", line 2748, in get_updates\n",
      "    result = self._post(\n",
      "  File \"C:\\ProgramData\\Anaconda3\\lib\\site-packages\\telegram\\bot.py\", line 258, in _post\n",
      "    return self.request.post(\n",
      "  File \"C:\\ProgramData\\Anaconda3\\lib\\site-packages\\telegram\\utils\\request.py\", line 349, in post\n",
      "    result = self._request_wrapper(\n",
      "  File \"C:\\ProgramData\\Anaconda3\\lib\\site-packages\\telegram\\utils\\request.py\", line 276, in _request_wrapper\n",
      "    raise Conflict(message)\n",
      "telegram.error.Conflict: Conflict: terminated by other getUpdates request; make sure that only one bot instance is running\n",
      "Error while getting Updates: Conflict: terminated by other getUpdates request; make sure that only one bot instance is running\n",
      "No error handlers are registered, logging exception.\n",
      "Traceback (most recent call last):\n",
      "  File \"C:\\ProgramData\\Anaconda3\\lib\\site-packages\\telegram\\ext\\updater.py\", line 465, in _network_loop_retry\n",
      "    if not action_cb():\n",
      "  File \"C:\\ProgramData\\Anaconda3\\lib\\site-packages\\telegram\\ext\\updater.py\", line 416, in polling_action_cb\n",
      "    updates = self.bot.get_updates(\n",
      "  File \"C:\\ProgramData\\Anaconda3\\lib\\site-packages\\telegram\\bot.py\", line 126, in decorator\n",
      "    result = func(*args, **kwargs)\n",
      "  File \"C:\\ProgramData\\Anaconda3\\lib\\site-packages\\telegram\\bot.py\", line 2748, in get_updates\n",
      "    result = self._post(\n",
      "  File \"C:\\ProgramData\\Anaconda3\\lib\\site-packages\\telegram\\bot.py\", line 258, in _post\n",
      "    return self.request.post(\n",
      "  File \"C:\\ProgramData\\Anaconda3\\lib\\site-packages\\telegram\\utils\\request.py\", line 349, in post\n",
      "    result = self._request_wrapper(\n",
      "  File \"C:\\ProgramData\\Anaconda3\\lib\\site-packages\\telegram\\utils\\request.py\", line 276, in _request_wrapper\n",
      "    raise Conflict(message)\n",
      "telegram.error.Conflict: Conflict: terminated by other getUpdates request; make sure that only one bot instance is running\n",
      "Error while getting Updates: Conflict: terminated by other getUpdates request; make sure that only one bot instance is running\n",
      "No error handlers are registered, logging exception.\n",
      "Traceback (most recent call last):\n",
      "  File \"C:\\ProgramData\\Anaconda3\\lib\\site-packages\\telegram\\ext\\updater.py\", line 465, in _network_loop_retry\n",
      "    if not action_cb():\n",
      "  File \"C:\\ProgramData\\Anaconda3\\lib\\site-packages\\telegram\\ext\\updater.py\", line 416, in polling_action_cb\n",
      "    updates = self.bot.get_updates(\n",
      "  File \"C:\\ProgramData\\Anaconda3\\lib\\site-packages\\telegram\\bot.py\", line 126, in decorator\n",
      "    result = func(*args, **kwargs)\n",
      "  File \"C:\\ProgramData\\Anaconda3\\lib\\site-packages\\telegram\\bot.py\", line 2748, in get_updates\n",
      "    result = self._post(\n",
      "  File \"C:\\ProgramData\\Anaconda3\\lib\\site-packages\\telegram\\bot.py\", line 258, in _post\n",
      "    return self.request.post(\n",
      "  File \"C:\\ProgramData\\Anaconda3\\lib\\site-packages\\telegram\\utils\\request.py\", line 349, in post\n",
      "    result = self._request_wrapper(\n",
      "  File \"C:\\ProgramData\\Anaconda3\\lib\\site-packages\\telegram\\utils\\request.py\", line 276, in _request_wrapper\n",
      "    raise Conflict(message)\n",
      "telegram.error.Conflict: Conflict: terminated by other getUpdates request; make sure that only one bot instance is running\n",
      "Error while getting Updates: Conflict: terminated by other getUpdates request; make sure that only one bot instance is running\n",
      "No error handlers are registered, logging exception.\n",
      "Traceback (most recent call last):\n",
      "  File \"C:\\ProgramData\\Anaconda3\\lib\\site-packages\\telegram\\ext\\updater.py\", line 465, in _network_loop_retry\n",
      "    if not action_cb():\n",
      "  File \"C:\\ProgramData\\Anaconda3\\lib\\site-packages\\telegram\\ext\\updater.py\", line 416, in polling_action_cb\n",
      "    updates = self.bot.get_updates(\n",
      "  File \"C:\\ProgramData\\Anaconda3\\lib\\site-packages\\telegram\\bot.py\", line 126, in decorator\n",
      "    result = func(*args, **kwargs)\n",
      "  File \"C:\\ProgramData\\Anaconda3\\lib\\site-packages\\telegram\\bot.py\", line 2748, in get_updates\n",
      "    result = self._post(\n",
      "  File \"C:\\ProgramData\\Anaconda3\\lib\\site-packages\\telegram\\bot.py\", line 258, in _post\n",
      "    return self.request.post(\n",
      "  File \"C:\\ProgramData\\Anaconda3\\lib\\site-packages\\telegram\\utils\\request.py\", line 349, in post\n",
      "    result = self._request_wrapper(\n",
      "  File \"C:\\ProgramData\\Anaconda3\\lib\\site-packages\\telegram\\utils\\request.py\", line 276, in _request_wrapper\n",
      "    raise Conflict(message)\n",
      "telegram.error.Conflict: Conflict: terminated by other getUpdates request; make sure that only one bot instance is running\n",
      "Error while getting Updates: Conflict: terminated by other getUpdates request; make sure that only one bot instance is running\n",
      "No error handlers are registered, logging exception.\n",
      "Traceback (most recent call last):\n",
      "  File \"C:\\ProgramData\\Anaconda3\\lib\\site-packages\\telegram\\ext\\updater.py\", line 465, in _network_loop_retry\n",
      "    if not action_cb():\n",
      "  File \"C:\\ProgramData\\Anaconda3\\lib\\site-packages\\telegram\\ext\\updater.py\", line 416, in polling_action_cb\n",
      "    updates = self.bot.get_updates(\n",
      "  File \"C:\\ProgramData\\Anaconda3\\lib\\site-packages\\telegram\\bot.py\", line 126, in decorator\n",
      "    result = func(*args, **kwargs)\n",
      "  File \"C:\\ProgramData\\Anaconda3\\lib\\site-packages\\telegram\\bot.py\", line 2748, in get_updates\n",
      "    result = self._post(\n",
      "  File \"C:\\ProgramData\\Anaconda3\\lib\\site-packages\\telegram\\bot.py\", line 258, in _post\n",
      "    return self.request.post(\n",
      "  File \"C:\\ProgramData\\Anaconda3\\lib\\site-packages\\telegram\\utils\\request.py\", line 349, in post\n",
      "    result = self._request_wrapper(\n",
      "  File \"C:\\ProgramData\\Anaconda3\\lib\\site-packages\\telegram\\utils\\request.py\", line 276, in _request_wrapper\n",
      "    raise Conflict(message)\n",
      "telegram.error.Conflict: Conflict: terminated by other getUpdates request; make sure that only one bot instance is running\n",
      "Error while getting Updates: Conflict: terminated by other getUpdates request; make sure that only one bot instance is running\n",
      "No error handlers are registered, logging exception.\n",
      "Traceback (most recent call last):\n",
      "  File \"C:\\ProgramData\\Anaconda3\\lib\\site-packages\\telegram\\ext\\updater.py\", line 465, in _network_loop_retry\n",
      "    if not action_cb():\n",
      "  File \"C:\\ProgramData\\Anaconda3\\lib\\site-packages\\telegram\\ext\\updater.py\", line 416, in polling_action_cb\n",
      "    updates = self.bot.get_updates(\n",
      "  File \"C:\\ProgramData\\Anaconda3\\lib\\site-packages\\telegram\\bot.py\", line 126, in decorator\n",
      "    result = func(*args, **kwargs)\n",
      "  File \"C:\\ProgramData\\Anaconda3\\lib\\site-packages\\telegram\\bot.py\", line 2748, in get_updates\n",
      "    result = self._post(\n",
      "  File \"C:\\ProgramData\\Anaconda3\\lib\\site-packages\\telegram\\bot.py\", line 258, in _post\n",
      "    return self.request.post(\n",
      "  File \"C:\\ProgramData\\Anaconda3\\lib\\site-packages\\telegram\\utils\\request.py\", line 349, in post\n",
      "    result = self._request_wrapper(\n",
      "  File \"C:\\ProgramData\\Anaconda3\\lib\\site-packages\\telegram\\utils\\request.py\", line 276, in _request_wrapper\n",
      "    raise Conflict(message)\n",
      "telegram.error.Conflict: Conflict: terminated by other getUpdates request; make sure that only one bot instance is running\n"
     ]
    },
    {
     "name": "stderr",
     "output_type": "stream",
     "text": [
      "Error while getting Updates: Conflict: terminated by other getUpdates request; make sure that only one bot instance is running\n",
      "No error handlers are registered, logging exception.\n",
      "Traceback (most recent call last):\n",
      "  File \"C:\\ProgramData\\Anaconda3\\lib\\site-packages\\telegram\\ext\\updater.py\", line 465, in _network_loop_retry\n",
      "    if not action_cb():\n",
      "  File \"C:\\ProgramData\\Anaconda3\\lib\\site-packages\\telegram\\ext\\updater.py\", line 416, in polling_action_cb\n",
      "    updates = self.bot.get_updates(\n",
      "  File \"C:\\ProgramData\\Anaconda3\\lib\\site-packages\\telegram\\bot.py\", line 126, in decorator\n",
      "    result = func(*args, **kwargs)\n",
      "  File \"C:\\ProgramData\\Anaconda3\\lib\\site-packages\\telegram\\bot.py\", line 2748, in get_updates\n",
      "    result = self._post(\n",
      "  File \"C:\\ProgramData\\Anaconda3\\lib\\site-packages\\telegram\\bot.py\", line 258, in _post\n",
      "    return self.request.post(\n",
      "  File \"C:\\ProgramData\\Anaconda3\\lib\\site-packages\\telegram\\utils\\request.py\", line 349, in post\n",
      "    result = self._request_wrapper(\n",
      "  File \"C:\\ProgramData\\Anaconda3\\lib\\site-packages\\telegram\\utils\\request.py\", line 276, in _request_wrapper\n",
      "    raise Conflict(message)\n",
      "telegram.error.Conflict: Conflict: terminated by other getUpdates request; make sure that only one bot instance is running\n",
      "Error while getting Updates: Conflict: terminated by other getUpdates request; make sure that only one bot instance is running\n",
      "No error handlers are registered, logging exception.\n",
      "Traceback (most recent call last):\n",
      "  File \"C:\\ProgramData\\Anaconda3\\lib\\site-packages\\telegram\\ext\\updater.py\", line 465, in _network_loop_retry\n",
      "    if not action_cb():\n",
      "  File \"C:\\ProgramData\\Anaconda3\\lib\\site-packages\\telegram\\ext\\updater.py\", line 416, in polling_action_cb\n",
      "    updates = self.bot.get_updates(\n",
      "  File \"C:\\ProgramData\\Anaconda3\\lib\\site-packages\\telegram\\bot.py\", line 126, in decorator\n",
      "    result = func(*args, **kwargs)\n",
      "  File \"C:\\ProgramData\\Anaconda3\\lib\\site-packages\\telegram\\bot.py\", line 2748, in get_updates\n",
      "    result = self._post(\n",
      "  File \"C:\\ProgramData\\Anaconda3\\lib\\site-packages\\telegram\\bot.py\", line 258, in _post\n",
      "    return self.request.post(\n",
      "  File \"C:\\ProgramData\\Anaconda3\\lib\\site-packages\\telegram\\utils\\request.py\", line 349, in post\n",
      "    result = self._request_wrapper(\n",
      "  File \"C:\\ProgramData\\Anaconda3\\lib\\site-packages\\telegram\\utils\\request.py\", line 276, in _request_wrapper\n",
      "    raise Conflict(message)\n",
      "telegram.error.Conflict: Conflict: terminated by other getUpdates request; make sure that only one bot instance is running\n",
      "Error while getting Updates: Conflict: terminated by other getUpdates request; make sure that only one bot instance is running\n",
      "No error handlers are registered, logging exception.\n",
      "Traceback (most recent call last):\n",
      "  File \"C:\\ProgramData\\Anaconda3\\lib\\site-packages\\telegram\\ext\\updater.py\", line 465, in _network_loop_retry\n",
      "    if not action_cb():\n",
      "  File \"C:\\ProgramData\\Anaconda3\\lib\\site-packages\\telegram\\ext\\updater.py\", line 416, in polling_action_cb\n",
      "    updates = self.bot.get_updates(\n",
      "  File \"C:\\ProgramData\\Anaconda3\\lib\\site-packages\\telegram\\bot.py\", line 126, in decorator\n",
      "    result = func(*args, **kwargs)\n",
      "  File \"C:\\ProgramData\\Anaconda3\\lib\\site-packages\\telegram\\bot.py\", line 2748, in get_updates\n",
      "    result = self._post(\n",
      "  File \"C:\\ProgramData\\Anaconda3\\lib\\site-packages\\telegram\\bot.py\", line 258, in _post\n",
      "    return self.request.post(\n",
      "  File \"C:\\ProgramData\\Anaconda3\\lib\\site-packages\\telegram\\utils\\request.py\", line 349, in post\n",
      "    result = self._request_wrapper(\n",
      "  File \"C:\\ProgramData\\Anaconda3\\lib\\site-packages\\telegram\\utils\\request.py\", line 276, in _request_wrapper\n",
      "    raise Conflict(message)\n",
      "telegram.error.Conflict: Conflict: terminated by other getUpdates request; make sure that only one bot instance is running\n",
      "Error while getting Updates: Conflict: terminated by other getUpdates request; make sure that only one bot instance is running\n",
      "No error handlers are registered, logging exception.\n",
      "Traceback (most recent call last):\n",
      "  File \"C:\\ProgramData\\Anaconda3\\lib\\site-packages\\telegram\\ext\\updater.py\", line 465, in _network_loop_retry\n",
      "    if not action_cb():\n",
      "  File \"C:\\ProgramData\\Anaconda3\\lib\\site-packages\\telegram\\ext\\updater.py\", line 416, in polling_action_cb\n",
      "    updates = self.bot.get_updates(\n",
      "  File \"C:\\ProgramData\\Anaconda3\\lib\\site-packages\\telegram\\bot.py\", line 126, in decorator\n",
      "    result = func(*args, **kwargs)\n",
      "  File \"C:\\ProgramData\\Anaconda3\\lib\\site-packages\\telegram\\bot.py\", line 2748, in get_updates\n",
      "    result = self._post(\n",
      "  File \"C:\\ProgramData\\Anaconda3\\lib\\site-packages\\telegram\\bot.py\", line 258, in _post\n",
      "    return self.request.post(\n",
      "  File \"C:\\ProgramData\\Anaconda3\\lib\\site-packages\\telegram\\utils\\request.py\", line 349, in post\n",
      "    result = self._request_wrapper(\n",
      "  File \"C:\\ProgramData\\Anaconda3\\lib\\site-packages\\telegram\\utils\\request.py\", line 276, in _request_wrapper\n",
      "    raise Conflict(message)\n",
      "telegram.error.Conflict: Conflict: terminated by other getUpdates request; make sure that only one bot instance is running\n",
      "Error while getting Updates: Conflict: terminated by other getUpdates request; make sure that only one bot instance is running\n",
      "No error handlers are registered, logging exception.\n",
      "Traceback (most recent call last):\n",
      "  File \"C:\\ProgramData\\Anaconda3\\lib\\site-packages\\telegram\\ext\\updater.py\", line 465, in _network_loop_retry\n",
      "    if not action_cb():\n",
      "  File \"C:\\ProgramData\\Anaconda3\\lib\\site-packages\\telegram\\ext\\updater.py\", line 416, in polling_action_cb\n",
      "    updates = self.bot.get_updates(\n",
      "  File \"C:\\ProgramData\\Anaconda3\\lib\\site-packages\\telegram\\bot.py\", line 126, in decorator\n",
      "    result = func(*args, **kwargs)\n",
      "  File \"C:\\ProgramData\\Anaconda3\\lib\\site-packages\\telegram\\bot.py\", line 2748, in get_updates\n",
      "    result = self._post(\n",
      "  File \"C:\\ProgramData\\Anaconda3\\lib\\site-packages\\telegram\\bot.py\", line 258, in _post\n",
      "    return self.request.post(\n",
      "  File \"C:\\ProgramData\\Anaconda3\\lib\\site-packages\\telegram\\utils\\request.py\", line 349, in post\n",
      "    result = self._request_wrapper(\n",
      "  File \"C:\\ProgramData\\Anaconda3\\lib\\site-packages\\telegram\\utils\\request.py\", line 276, in _request_wrapper\n",
      "    raise Conflict(message)\n",
      "telegram.error.Conflict: Conflict: terminated by other getUpdates request; make sure that only one bot instance is running\n",
      "Error while getting Updates: Conflict: terminated by other getUpdates request; make sure that only one bot instance is running\n",
      "No error handlers are registered, logging exception.\n",
      "Traceback (most recent call last):\n",
      "  File \"C:\\ProgramData\\Anaconda3\\lib\\site-packages\\telegram\\ext\\updater.py\", line 465, in _network_loop_retry\n",
      "    if not action_cb():\n",
      "  File \"C:\\ProgramData\\Anaconda3\\lib\\site-packages\\telegram\\ext\\updater.py\", line 416, in polling_action_cb\n",
      "    updates = self.bot.get_updates(\n",
      "  File \"C:\\ProgramData\\Anaconda3\\lib\\site-packages\\telegram\\bot.py\", line 126, in decorator\n",
      "    result = func(*args, **kwargs)\n",
      "  File \"C:\\ProgramData\\Anaconda3\\lib\\site-packages\\telegram\\bot.py\", line 2748, in get_updates\n",
      "    result = self._post(\n",
      "  File \"C:\\ProgramData\\Anaconda3\\lib\\site-packages\\telegram\\bot.py\", line 258, in _post\n",
      "    return self.request.post(\n",
      "  File \"C:\\ProgramData\\Anaconda3\\lib\\site-packages\\telegram\\utils\\request.py\", line 349, in post\n",
      "    result = self._request_wrapper(\n",
      "  File \"C:\\ProgramData\\Anaconda3\\lib\\site-packages\\telegram\\utils\\request.py\", line 276, in _request_wrapper\n",
      "    raise Conflict(message)\n",
      "telegram.error.Conflict: Conflict: terminated by other getUpdates request; make sure that only one bot instance is running\n",
      "Error while getting Updates: Conflict: terminated by other getUpdates request; make sure that only one bot instance is running\n",
      "No error handlers are registered, logging exception.\n",
      "Traceback (most recent call last):\n",
      "  File \"C:\\ProgramData\\Anaconda3\\lib\\site-packages\\telegram\\ext\\updater.py\", line 465, in _network_loop_retry\n",
      "    if not action_cb():\n",
      "  File \"C:\\ProgramData\\Anaconda3\\lib\\site-packages\\telegram\\ext\\updater.py\", line 416, in polling_action_cb\n",
      "    updates = self.bot.get_updates(\n",
      "  File \"C:\\ProgramData\\Anaconda3\\lib\\site-packages\\telegram\\bot.py\", line 126, in decorator\n",
      "    result = func(*args, **kwargs)\n",
      "  File \"C:\\ProgramData\\Anaconda3\\lib\\site-packages\\telegram\\bot.py\", line 2748, in get_updates\n",
      "    result = self._post(\n",
      "  File \"C:\\ProgramData\\Anaconda3\\lib\\site-packages\\telegram\\bot.py\", line 258, in _post\n",
      "    return self.request.post(\n",
      "  File \"C:\\ProgramData\\Anaconda3\\lib\\site-packages\\telegram\\utils\\request.py\", line 349, in post\n",
      "    result = self._request_wrapper(\n",
      "  File \"C:\\ProgramData\\Anaconda3\\lib\\site-packages\\telegram\\utils\\request.py\", line 276, in _request_wrapper\n",
      "    raise Conflict(message)\n",
      "telegram.error.Conflict: Conflict: terminated by other getUpdates request; make sure that only one bot instance is running\n"
     ]
    },
    {
     "name": "stderr",
     "output_type": "stream",
     "text": [
      "Error while getting Updates: Conflict: terminated by other getUpdates request; make sure that only one bot instance is running\n",
      "No error handlers are registered, logging exception.\n",
      "Traceback (most recent call last):\n",
      "  File \"C:\\ProgramData\\Anaconda3\\lib\\site-packages\\telegram\\ext\\updater.py\", line 465, in _network_loop_retry\n",
      "    if not action_cb():\n",
      "  File \"C:\\ProgramData\\Anaconda3\\lib\\site-packages\\telegram\\ext\\updater.py\", line 416, in polling_action_cb\n",
      "    updates = self.bot.get_updates(\n",
      "  File \"C:\\ProgramData\\Anaconda3\\lib\\site-packages\\telegram\\bot.py\", line 126, in decorator\n",
      "    result = func(*args, **kwargs)\n",
      "  File \"C:\\ProgramData\\Anaconda3\\lib\\site-packages\\telegram\\bot.py\", line 2748, in get_updates\n",
      "    result = self._post(\n",
      "  File \"C:\\ProgramData\\Anaconda3\\lib\\site-packages\\telegram\\bot.py\", line 258, in _post\n",
      "    return self.request.post(\n",
      "  File \"C:\\ProgramData\\Anaconda3\\lib\\site-packages\\telegram\\utils\\request.py\", line 349, in post\n",
      "    result = self._request_wrapper(\n",
      "  File \"C:\\ProgramData\\Anaconda3\\lib\\site-packages\\telegram\\utils\\request.py\", line 276, in _request_wrapper\n",
      "    raise Conflict(message)\n",
      "telegram.error.Conflict: Conflict: terminated by other getUpdates request; make sure that only one bot instance is running\n",
      "Error while getting Updates: Conflict: terminated by other getUpdates request; make sure that only one bot instance is running\n",
      "No error handlers are registered, logging exception.\n",
      "Traceback (most recent call last):\n",
      "  File \"C:\\ProgramData\\Anaconda3\\lib\\site-packages\\telegram\\ext\\updater.py\", line 465, in _network_loop_retry\n",
      "    if not action_cb():\n",
      "  File \"C:\\ProgramData\\Anaconda3\\lib\\site-packages\\telegram\\ext\\updater.py\", line 416, in polling_action_cb\n",
      "    updates = self.bot.get_updates(\n",
      "  File \"C:\\ProgramData\\Anaconda3\\lib\\site-packages\\telegram\\bot.py\", line 126, in decorator\n",
      "    result = func(*args, **kwargs)\n",
      "  File \"C:\\ProgramData\\Anaconda3\\lib\\site-packages\\telegram\\bot.py\", line 2748, in get_updates\n",
      "    result = self._post(\n",
      "  File \"C:\\ProgramData\\Anaconda3\\lib\\site-packages\\telegram\\bot.py\", line 258, in _post\n",
      "    return self.request.post(\n",
      "  File \"C:\\ProgramData\\Anaconda3\\lib\\site-packages\\telegram\\utils\\request.py\", line 349, in post\n",
      "    result = self._request_wrapper(\n",
      "  File \"C:\\ProgramData\\Anaconda3\\lib\\site-packages\\telegram\\utils\\request.py\", line 276, in _request_wrapper\n",
      "    raise Conflict(message)\n",
      "telegram.error.Conflict: Conflict: terminated by other getUpdates request; make sure that only one bot instance is running\n",
      "Error while getting Updates: Conflict: terminated by other getUpdates request; make sure that only one bot instance is running\n",
      "No error handlers are registered, logging exception.\n",
      "Traceback (most recent call last):\n",
      "  File \"C:\\ProgramData\\Anaconda3\\lib\\site-packages\\telegram\\ext\\updater.py\", line 465, in _network_loop_retry\n",
      "    if not action_cb():\n",
      "  File \"C:\\ProgramData\\Anaconda3\\lib\\site-packages\\telegram\\ext\\updater.py\", line 416, in polling_action_cb\n",
      "    updates = self.bot.get_updates(\n",
      "  File \"C:\\ProgramData\\Anaconda3\\lib\\site-packages\\telegram\\bot.py\", line 126, in decorator\n",
      "    result = func(*args, **kwargs)\n",
      "  File \"C:\\ProgramData\\Anaconda3\\lib\\site-packages\\telegram\\bot.py\", line 2748, in get_updates\n",
      "    result = self._post(\n",
      "  File \"C:\\ProgramData\\Anaconda3\\lib\\site-packages\\telegram\\bot.py\", line 258, in _post\n",
      "    return self.request.post(\n",
      "  File \"C:\\ProgramData\\Anaconda3\\lib\\site-packages\\telegram\\utils\\request.py\", line 349, in post\n",
      "    result = self._request_wrapper(\n",
      "  File \"C:\\ProgramData\\Anaconda3\\lib\\site-packages\\telegram\\utils\\request.py\", line 276, in _request_wrapper\n",
      "    raise Conflict(message)\n",
      "telegram.error.Conflict: Conflict: terminated by other getUpdates request; make sure that only one bot instance is running\n",
      "Error while getting Updates: Conflict: terminated by other getUpdates request; make sure that only one bot instance is running\n",
      "No error handlers are registered, logging exception.\n",
      "Traceback (most recent call last):\n",
      "  File \"C:\\ProgramData\\Anaconda3\\lib\\site-packages\\telegram\\ext\\updater.py\", line 465, in _network_loop_retry\n",
      "    if not action_cb():\n",
      "  File \"C:\\ProgramData\\Anaconda3\\lib\\site-packages\\telegram\\ext\\updater.py\", line 416, in polling_action_cb\n",
      "    updates = self.bot.get_updates(\n",
      "  File \"C:\\ProgramData\\Anaconda3\\lib\\site-packages\\telegram\\bot.py\", line 126, in decorator\n",
      "    result = func(*args, **kwargs)\n",
      "  File \"C:\\ProgramData\\Anaconda3\\lib\\site-packages\\telegram\\bot.py\", line 2748, in get_updates\n",
      "    result = self._post(\n",
      "  File \"C:\\ProgramData\\Anaconda3\\lib\\site-packages\\telegram\\bot.py\", line 258, in _post\n",
      "    return self.request.post(\n",
      "  File \"C:\\ProgramData\\Anaconda3\\lib\\site-packages\\telegram\\utils\\request.py\", line 349, in post\n",
      "    result = self._request_wrapper(\n",
      "  File \"C:\\ProgramData\\Anaconda3\\lib\\site-packages\\telegram\\utils\\request.py\", line 276, in _request_wrapper\n",
      "    raise Conflict(message)\n",
      "telegram.error.Conflict: Conflict: terminated by other getUpdates request; make sure that only one bot instance is running\n",
      "Error while getting Updates: Conflict: terminated by other getUpdates request; make sure that only one bot instance is running\n",
      "No error handlers are registered, logging exception.\n",
      "Traceback (most recent call last):\n",
      "  File \"C:\\ProgramData\\Anaconda3\\lib\\site-packages\\telegram\\ext\\updater.py\", line 465, in _network_loop_retry\n",
      "    if not action_cb():\n",
      "  File \"C:\\ProgramData\\Anaconda3\\lib\\site-packages\\telegram\\ext\\updater.py\", line 416, in polling_action_cb\n",
      "    updates = self.bot.get_updates(\n",
      "  File \"C:\\ProgramData\\Anaconda3\\lib\\site-packages\\telegram\\bot.py\", line 126, in decorator\n",
      "    result = func(*args, **kwargs)\n",
      "  File \"C:\\ProgramData\\Anaconda3\\lib\\site-packages\\telegram\\bot.py\", line 2748, in get_updates\n",
      "    result = self._post(\n",
      "  File \"C:\\ProgramData\\Anaconda3\\lib\\site-packages\\telegram\\bot.py\", line 258, in _post\n",
      "    return self.request.post(\n",
      "  File \"C:\\ProgramData\\Anaconda3\\lib\\site-packages\\telegram\\utils\\request.py\", line 349, in post\n",
      "    result = self._request_wrapper(\n",
      "  File \"C:\\ProgramData\\Anaconda3\\lib\\site-packages\\telegram\\utils\\request.py\", line 276, in _request_wrapper\n",
      "    raise Conflict(message)\n",
      "telegram.error.Conflict: Conflict: terminated by other getUpdates request; make sure that only one bot instance is running\n",
      "Error while getting Updates: Conflict: terminated by other getUpdates request; make sure that only one bot instance is running\n",
      "No error handlers are registered, logging exception.\n",
      "Traceback (most recent call last):\n",
      "  File \"C:\\ProgramData\\Anaconda3\\lib\\site-packages\\telegram\\ext\\updater.py\", line 465, in _network_loop_retry\n",
      "    if not action_cb():\n",
      "  File \"C:\\ProgramData\\Anaconda3\\lib\\site-packages\\telegram\\ext\\updater.py\", line 416, in polling_action_cb\n",
      "    updates = self.bot.get_updates(\n",
      "  File \"C:\\ProgramData\\Anaconda3\\lib\\site-packages\\telegram\\bot.py\", line 126, in decorator\n",
      "    result = func(*args, **kwargs)\n",
      "  File \"C:\\ProgramData\\Anaconda3\\lib\\site-packages\\telegram\\bot.py\", line 2748, in get_updates\n",
      "    result = self._post(\n",
      "  File \"C:\\ProgramData\\Anaconda3\\lib\\site-packages\\telegram\\bot.py\", line 258, in _post\n",
      "    return self.request.post(\n",
      "  File \"C:\\ProgramData\\Anaconda3\\lib\\site-packages\\telegram\\utils\\request.py\", line 349, in post\n",
      "    result = self._request_wrapper(\n",
      "  File \"C:\\ProgramData\\Anaconda3\\lib\\site-packages\\telegram\\utils\\request.py\", line 276, in _request_wrapper\n",
      "    raise Conflict(message)\n",
      "telegram.error.Conflict: Conflict: terminated by other getUpdates request; make sure that only one bot instance is running\n",
      "Error while getting Updates: Conflict: terminated by other getUpdates request; make sure that only one bot instance is running\n",
      "No error handlers are registered, logging exception.\n",
      "Traceback (most recent call last):\n",
      "  File \"C:\\ProgramData\\Anaconda3\\lib\\site-packages\\telegram\\ext\\updater.py\", line 465, in _network_loop_retry\n",
      "    if not action_cb():\n",
      "  File \"C:\\ProgramData\\Anaconda3\\lib\\site-packages\\telegram\\ext\\updater.py\", line 416, in polling_action_cb\n",
      "    updates = self.bot.get_updates(\n",
      "  File \"C:\\ProgramData\\Anaconda3\\lib\\site-packages\\telegram\\bot.py\", line 126, in decorator\n",
      "    result = func(*args, **kwargs)\n",
      "  File \"C:\\ProgramData\\Anaconda3\\lib\\site-packages\\telegram\\bot.py\", line 2748, in get_updates\n",
      "    result = self._post(\n",
      "  File \"C:\\ProgramData\\Anaconda3\\lib\\site-packages\\telegram\\bot.py\", line 258, in _post\n",
      "    return self.request.post(\n",
      "  File \"C:\\ProgramData\\Anaconda3\\lib\\site-packages\\telegram\\utils\\request.py\", line 349, in post\n",
      "    result = self._request_wrapper(\n",
      "  File \"C:\\ProgramData\\Anaconda3\\lib\\site-packages\\telegram\\utils\\request.py\", line 276, in _request_wrapper\n",
      "    raise Conflict(message)\n",
      "telegram.error.Conflict: Conflict: terminated by other getUpdates request; make sure that only one bot instance is running\n"
     ]
    },
    {
     "name": "stderr",
     "output_type": "stream",
     "text": [
      "Error while getting Updates: Conflict: terminated by other getUpdates request; make sure that only one bot instance is running\n",
      "No error handlers are registered, logging exception.\n",
      "Traceback (most recent call last):\n",
      "  File \"C:\\ProgramData\\Anaconda3\\lib\\site-packages\\telegram\\ext\\updater.py\", line 465, in _network_loop_retry\n",
      "    if not action_cb():\n",
      "  File \"C:\\ProgramData\\Anaconda3\\lib\\site-packages\\telegram\\ext\\updater.py\", line 416, in polling_action_cb\n",
      "    updates = self.bot.get_updates(\n",
      "  File \"C:\\ProgramData\\Anaconda3\\lib\\site-packages\\telegram\\bot.py\", line 126, in decorator\n",
      "    result = func(*args, **kwargs)\n",
      "  File \"C:\\ProgramData\\Anaconda3\\lib\\site-packages\\telegram\\bot.py\", line 2748, in get_updates\n",
      "    result = self._post(\n",
      "  File \"C:\\ProgramData\\Anaconda3\\lib\\site-packages\\telegram\\bot.py\", line 258, in _post\n",
      "    return self.request.post(\n",
      "  File \"C:\\ProgramData\\Anaconda3\\lib\\site-packages\\telegram\\utils\\request.py\", line 349, in post\n",
      "    result = self._request_wrapper(\n",
      "  File \"C:\\ProgramData\\Anaconda3\\lib\\site-packages\\telegram\\utils\\request.py\", line 276, in _request_wrapper\n",
      "    raise Conflict(message)\n",
      "telegram.error.Conflict: Conflict: terminated by other getUpdates request; make sure that only one bot instance is running\n",
      "Error while getting Updates: Conflict: terminated by other getUpdates request; make sure that only one bot instance is running\n",
      "No error handlers are registered, logging exception.\n",
      "Traceback (most recent call last):\n",
      "  File \"C:\\ProgramData\\Anaconda3\\lib\\site-packages\\telegram\\ext\\updater.py\", line 465, in _network_loop_retry\n",
      "    if not action_cb():\n",
      "  File \"C:\\ProgramData\\Anaconda3\\lib\\site-packages\\telegram\\ext\\updater.py\", line 416, in polling_action_cb\n",
      "    updates = self.bot.get_updates(\n",
      "  File \"C:\\ProgramData\\Anaconda3\\lib\\site-packages\\telegram\\bot.py\", line 126, in decorator\n",
      "    result = func(*args, **kwargs)\n",
      "  File \"C:\\ProgramData\\Anaconda3\\lib\\site-packages\\telegram\\bot.py\", line 2748, in get_updates\n",
      "    result = self._post(\n",
      "  File \"C:\\ProgramData\\Anaconda3\\lib\\site-packages\\telegram\\bot.py\", line 258, in _post\n",
      "    return self.request.post(\n",
      "  File \"C:\\ProgramData\\Anaconda3\\lib\\site-packages\\telegram\\utils\\request.py\", line 349, in post\n",
      "    result = self._request_wrapper(\n",
      "  File \"C:\\ProgramData\\Anaconda3\\lib\\site-packages\\telegram\\utils\\request.py\", line 276, in _request_wrapper\n",
      "    raise Conflict(message)\n",
      "telegram.error.Conflict: Conflict: terminated by other getUpdates request; make sure that only one bot instance is running\n",
      "Error while getting Updates: Conflict: terminated by other getUpdates request; make sure that only one bot instance is running\n",
      "No error handlers are registered, logging exception.\n",
      "Traceback (most recent call last):\n",
      "  File \"C:\\ProgramData\\Anaconda3\\lib\\site-packages\\telegram\\ext\\updater.py\", line 465, in _network_loop_retry\n",
      "    if not action_cb():\n",
      "  File \"C:\\ProgramData\\Anaconda3\\lib\\site-packages\\telegram\\ext\\updater.py\", line 416, in polling_action_cb\n",
      "    updates = self.bot.get_updates(\n",
      "  File \"C:\\ProgramData\\Anaconda3\\lib\\site-packages\\telegram\\bot.py\", line 126, in decorator\n",
      "    result = func(*args, **kwargs)\n",
      "  File \"C:\\ProgramData\\Anaconda3\\lib\\site-packages\\telegram\\bot.py\", line 2748, in get_updates\n",
      "    result = self._post(\n",
      "  File \"C:\\ProgramData\\Anaconda3\\lib\\site-packages\\telegram\\bot.py\", line 258, in _post\n",
      "    return self.request.post(\n",
      "  File \"C:\\ProgramData\\Anaconda3\\lib\\site-packages\\telegram\\utils\\request.py\", line 349, in post\n",
      "    result = self._request_wrapper(\n",
      "  File \"C:\\ProgramData\\Anaconda3\\lib\\site-packages\\telegram\\utils\\request.py\", line 276, in _request_wrapper\n",
      "    raise Conflict(message)\n",
      "telegram.error.Conflict: Conflict: terminated by other getUpdates request; make sure that only one bot instance is running\n",
      "Error while getting Updates: Conflict: terminated by other getUpdates request; make sure that only one bot instance is running\n",
      "No error handlers are registered, logging exception.\n",
      "Traceback (most recent call last):\n",
      "  File \"C:\\ProgramData\\Anaconda3\\lib\\site-packages\\telegram\\ext\\updater.py\", line 465, in _network_loop_retry\n",
      "    if not action_cb():\n",
      "  File \"C:\\ProgramData\\Anaconda3\\lib\\site-packages\\telegram\\ext\\updater.py\", line 416, in polling_action_cb\n",
      "    updates = self.bot.get_updates(\n",
      "  File \"C:\\ProgramData\\Anaconda3\\lib\\site-packages\\telegram\\bot.py\", line 126, in decorator\n",
      "    result = func(*args, **kwargs)\n",
      "  File \"C:\\ProgramData\\Anaconda3\\lib\\site-packages\\telegram\\bot.py\", line 2748, in get_updates\n",
      "    result = self._post(\n",
      "  File \"C:\\ProgramData\\Anaconda3\\lib\\site-packages\\telegram\\bot.py\", line 258, in _post\n",
      "    return self.request.post(\n",
      "  File \"C:\\ProgramData\\Anaconda3\\lib\\site-packages\\telegram\\utils\\request.py\", line 349, in post\n",
      "    result = self._request_wrapper(\n",
      "  File \"C:\\ProgramData\\Anaconda3\\lib\\site-packages\\telegram\\utils\\request.py\", line 276, in _request_wrapper\n",
      "    raise Conflict(message)\n",
      "telegram.error.Conflict: Conflict: terminated by other getUpdates request; make sure that only one bot instance is running\n",
      "Error while getting Updates: Conflict: terminated by other getUpdates request; make sure that only one bot instance is running\n",
      "No error handlers are registered, logging exception.\n",
      "Traceback (most recent call last):\n",
      "  File \"C:\\ProgramData\\Anaconda3\\lib\\site-packages\\telegram\\ext\\updater.py\", line 465, in _network_loop_retry\n",
      "    if not action_cb():\n",
      "  File \"C:\\ProgramData\\Anaconda3\\lib\\site-packages\\telegram\\ext\\updater.py\", line 416, in polling_action_cb\n",
      "    updates = self.bot.get_updates(\n",
      "  File \"C:\\ProgramData\\Anaconda3\\lib\\site-packages\\telegram\\bot.py\", line 126, in decorator\n",
      "    result = func(*args, **kwargs)\n",
      "  File \"C:\\ProgramData\\Anaconda3\\lib\\site-packages\\telegram\\bot.py\", line 2748, in get_updates\n",
      "    result = self._post(\n",
      "  File \"C:\\ProgramData\\Anaconda3\\lib\\site-packages\\telegram\\bot.py\", line 258, in _post\n",
      "    return self.request.post(\n",
      "  File \"C:\\ProgramData\\Anaconda3\\lib\\site-packages\\telegram\\utils\\request.py\", line 349, in post\n",
      "    result = self._request_wrapper(\n",
      "  File \"C:\\ProgramData\\Anaconda3\\lib\\site-packages\\telegram\\utils\\request.py\", line 276, in _request_wrapper\n",
      "    raise Conflict(message)\n",
      "telegram.error.Conflict: Conflict: terminated by other getUpdates request; make sure that only one bot instance is running\n",
      "Error while getting Updates: Conflict: terminated by other getUpdates request; make sure that only one bot instance is running\n",
      "No error handlers are registered, logging exception.\n",
      "Traceback (most recent call last):\n",
      "  File \"C:\\ProgramData\\Anaconda3\\lib\\site-packages\\telegram\\ext\\updater.py\", line 465, in _network_loop_retry\n",
      "    if not action_cb():\n",
      "  File \"C:\\ProgramData\\Anaconda3\\lib\\site-packages\\telegram\\ext\\updater.py\", line 416, in polling_action_cb\n",
      "    updates = self.bot.get_updates(\n",
      "  File \"C:\\ProgramData\\Anaconda3\\lib\\site-packages\\telegram\\bot.py\", line 126, in decorator\n",
      "    result = func(*args, **kwargs)\n",
      "  File \"C:\\ProgramData\\Anaconda3\\lib\\site-packages\\telegram\\bot.py\", line 2748, in get_updates\n",
      "    result = self._post(\n",
      "  File \"C:\\ProgramData\\Anaconda3\\lib\\site-packages\\telegram\\bot.py\", line 258, in _post\n",
      "    return self.request.post(\n",
      "  File \"C:\\ProgramData\\Anaconda3\\lib\\site-packages\\telegram\\utils\\request.py\", line 349, in post\n",
      "    result = self._request_wrapper(\n",
      "  File \"C:\\ProgramData\\Anaconda3\\lib\\site-packages\\telegram\\utils\\request.py\", line 276, in _request_wrapper\n",
      "    raise Conflict(message)\n",
      "telegram.error.Conflict: Conflict: terminated by other getUpdates request; make sure that only one bot instance is running\n"
     ]
    }
   ],
   "source": [
    "updater.idle()"
   ]
  },
  {
   "cell_type": "code",
   "execution_count": null,
   "id": "bda1e411",
   "metadata": {},
   "outputs": [],
   "source": []
  }
 ],
 "metadata": {
  "kernelspec": {
   "display_name": "Python 3 (ipykernel)",
   "language": "python",
   "name": "python3"
  },
  "language_info": {
   "codemirror_mode": {
    "name": "ipython",
    "version": 3
   },
   "file_extension": ".py",
   "mimetype": "text/x-python",
   "name": "python",
   "nbconvert_exporter": "python",
   "pygments_lexer": "ipython3",
   "version": "3.9.7"
  }
 },
 "nbformat": 4,
 "nbformat_minor": 5
}
